Traceback (most recent call last):
  File "/Users/apple/Documents/github/MyJupyterBookShelf/.venv/lib/python3.7/site-packages/jupyter_cache/executors/utils.py", line 56, in single_nb_execution
    record_timing=False,
  File "/Users/apple/Documents/github/MyJupyterBookShelf/.venv/lib/python3.7/site-packages/nbclient/client.py", line 1082, in execute
    return NotebookClient(nb=nb, resources=resources, km=km, **kwargs).execute()
  File "/Users/apple/Documents/github/MyJupyterBookShelf/.venv/lib/python3.7/site-packages/nbclient/util.py", line 74, in wrapped
    return just_run(coro(*args, **kwargs))
  File "/Users/apple/Documents/github/MyJupyterBookShelf/.venv/lib/python3.7/site-packages/nbclient/util.py", line 53, in just_run
    return loop.run_until_complete(coro)
  File "/Users/apple/.pyenv/versions/3.7.5/lib/python3.7/asyncio/base_events.py", line 579, in run_until_complete
    return future.result()
  File "/Users/apple/Documents/github/MyJupyterBookShelf/.venv/lib/python3.7/site-packages/nbclient/client.py", line 536, in async_execute
    cell, index, execution_count=self.code_cells_executed + 1
  File "/Users/apple/Documents/github/MyJupyterBookShelf/.venv/lib/python3.7/site-packages/nbclient/client.py", line 827, in async_execute_cell
    self._check_raise_for_error(cell, exec_reply)
  File "/Users/apple/Documents/github/MyJupyterBookShelf/.venv/lib/python3.7/site-packages/nbclient/client.py", line 735, in _check_raise_for_error
    raise CellExecutionError.from_cell_and_msg(cell, exec_reply['content'])
nbclient.exceptions.CellExecutionError: An error occurred while executing the following cell:
------------------
import statsmodels
from statsmodels.tsa.stattools import adfuller


def test_stationarity(ts):
    
    # „É≠„Éº„É™„É≥„Ç∞Áµ±Ë®à„ÅÆÊ±∫ÂÆö
    rolmean = pd.rolling_mean(ts, window=12)
    rolstd = pd.rolling_std(ts, window=12)
    
    # „É≠„Éº„É™„É≥„Ç∞Áµ±Ë®à„ÅÆ„Éó„É≠„ÉÉ„Éà
    arig = plt.plot(ts, color='blue', label='Original')
    mean = plt.plot(rolmean, color='red', label='Rolling Mean')
    std = plt.plot(rolstd, color='black', label='Rolling Std')
    plt.legend(loc='best')
    plt.title('Rolling Mean & Standard Deviation')
    plt.show(block=False)
    
    # „Éá„Ç£„ÉÉ„Ç≠„Éº„Éï„É©„ÉºÊ§úÂÆö
    print('Results of Dickey-Fuller Test')
    dftest = adfuller(ts, autolog='AIC')
    dfoutput = pd.Series(dftest[0:4], index=['Test Statistic', 'p-value', '#Lags Used', 'Number of Observations Used'])
    for key, value in dftest[4].items():
        dfoutput['Critical Value (%s)'%key] = value
    print(dfoutput)
------------------

[0;31m---------------------------------------------------------------------------[0m
[0;31mModuleNotFoundError[0m                       Traceback (most recent call last)
[0;32m<ipython-input-11-a1eed5831135>[0m in [0;36m<module>[0;34m[0m
[0;32m----> 1[0;31m [0;32mimport[0m [0mstatsmodels[0m[0;34m[0m[0;34m[0m[0m
[0m[1;32m      2[0m [0;32mfrom[0m [0mstatsmodels[0m[0;34m.[0m[0mtsa[0m[0;34m.[0m[0mstattools[0m [0;32mimport[0m [0madfuller[0m[0;34m[0m[0;34m[0m[0m
[1;32m      3[0m [0;34m[0m[0m
[1;32m      4[0m [0;34m[0m[0m
[1;32m      5[0m [0;32mdef[0m [0mtest_stationarity[0m[0;34m([0m[0mts[0m[0;34m)[0m[0;34m:[0m[0;34m[0m[0;34m[0m[0m

[0;31mModuleNotFoundError[0m: No module named 'statsmodels'
ModuleNotFoundError: No module named 'statsmodels'

